Using bfloat16 Automatic Mixed Precision (AMP)
GPU available: True (cuda), used: True
TPU available: False, using: 0 TPU cores
IPU available: False, using: 0 IPUs
HPU available: False, using: 0 HPUs
Traceback (most recent call last):
  File "/home/philipdb/anaconda3/envs/tdt4265/lib/python3.10/site-packages/pandas/core/indexes/base.py", line 3805, in get_loc
    return self._engine.get_loc(casted_key)
  File "index.pyx", line 167, in pandas._libs.index.IndexEngine.get_loc
  File "index.pyx", line 196, in pandas._libs.index.IndexEngine.get_loc
  File "pandas/_libs/hashtable_class_helper.pxi", line 7081, in pandas._libs.hashtable.PyObjectHashTable.get_item
  File "pandas/_libs/hashtable_class_helper.pxi", line 7089, in pandas._libs.hashtable.PyObjectHashTable.get_item
KeyError: 'img_number'
The above exception was the direct cause of the following exception:
Traceback (most recent call last):
  File "/home/philipdb/dat2/datsyn_project/pytorch-lightning-template/trainer.py", line 103, in <module>
    trainer.fit(model, datamodule=dm)
  File "/home/philipdb/anaconda3/envs/tdt4265/lib/python3.10/site-packages/lightning/pytorch/trainer/trainer.py", line 532, in fit
    call._call_and_handle_interrupt(
  File "/home/philipdb/anaconda3/envs/tdt4265/lib/python3.10/site-packages/lightning/pytorch/trainer/call.py", line 43, in _call_and_handle_interrupt
    return trainer_fn(*args, **kwargs)
  File "/home/philipdb/anaconda3/envs/tdt4265/lib/python3.10/site-packages/lightning/pytorch/trainer/trainer.py", line 571, in _fit_impl
    self._run(model, ckpt_path=ckpt_path)
  File "/home/philipdb/anaconda3/envs/tdt4265/lib/python3.10/site-packages/lightning/pytorch/trainer/trainer.py", line 941, in _run
    call._call_setup_hook(self)  # allow user to setup lightning_module in accelerator environment
  File "/home/philipdb/anaconda3/envs/tdt4265/lib/python3.10/site-packages/lightning/pytorch/trainer/call.py", line 85, in _call_setup_hook
    _call_lightning_datamodule_hook(trainer, "setup", stage=fn)
  File "/home/philipdb/anaconda3/envs/tdt4265/lib/python3.10/site-packages/lightning/pytorch/trainer/call.py", line 166, in _call_lightning_datamodule_hook
    return fn(*args, **kwargs)
  File "/home/philipdb/dat2/datsyn_project/pytorch-lightning-template/datamodule_1.py", line 94, in setup
    full_dataset = BoundingBoxDataset(img_dir=os.path.join(self.data_root,self.train_str),
  File "/home/philipdb/dat2/datsyn_project/pytorch-lightning-template/datamodule_1.py", line 19, in __init__
    self.unique_images = self.annotations['img_number'].tolist()
  File "/home/philipdb/anaconda3/envs/tdt4265/lib/python3.10/site-packages/pandas/core/frame.py", line 4090, in __getitem__
    indexer = self.columns.get_loc(key)
  File "/home/philipdb/anaconda3/envs/tdt4265/lib/python3.10/site-packages/pandas/core/indexes/base.py", line 3812, in get_loc
    raise KeyError(key) from err
KeyError: 'img_number'
Traceback (most recent call last):
  File "/home/philipdb/anaconda3/envs/tdt4265/lib/python3.10/site-packages/pandas/core/indexes/base.py", line 3805, in get_loc
    return self._engine.get_loc(casted_key)
  File "index.pyx", line 167, in pandas._libs.index.IndexEngine.get_loc
  File "index.pyx", line 196, in pandas._libs.index.IndexEngine.get_loc
  File "pandas/_libs/hashtable_class_helper.pxi", line 7081, in pandas._libs.hashtable.PyObjectHashTable.get_item
  File "pandas/_libs/hashtable_class_helper.pxi", line 7089, in pandas._libs.hashtable.PyObjectHashTable.get_item
KeyError: 'img_number'
The above exception was the direct cause of the following exception:
Traceback (most recent call last):
  File "/home/philipdb/dat2/datsyn_project/pytorch-lightning-template/trainer.py", line 103, in <module>
    trainer.fit(model, datamodule=dm)
  File "/home/philipdb/anaconda3/envs/tdt4265/lib/python3.10/site-packages/lightning/pytorch/trainer/trainer.py", line 532, in fit
    call._call_and_handle_interrupt(
  File "/home/philipdb/anaconda3/envs/tdt4265/lib/python3.10/site-packages/lightning/pytorch/trainer/call.py", line 43, in _call_and_handle_interrupt
    return trainer_fn(*args, **kwargs)
  File "/home/philipdb/anaconda3/envs/tdt4265/lib/python3.10/site-packages/lightning/pytorch/trainer/trainer.py", line 571, in _fit_impl
    self._run(model, ckpt_path=ckpt_path)
  File "/home/philipdb/anaconda3/envs/tdt4265/lib/python3.10/site-packages/lightning/pytorch/trainer/trainer.py", line 941, in _run
    call._call_setup_hook(self)  # allow user to setup lightning_module in accelerator environment
  File "/home/philipdb/anaconda3/envs/tdt4265/lib/python3.10/site-packages/lightning/pytorch/trainer/call.py", line 85, in _call_setup_hook
    _call_lightning_datamodule_hook(trainer, "setup", stage=fn)
  File "/home/philipdb/anaconda3/envs/tdt4265/lib/python3.10/site-packages/lightning/pytorch/trainer/call.py", line 166, in _call_lightning_datamodule_hook
    return fn(*args, **kwargs)
  File "/home/philipdb/dat2/datsyn_project/pytorch-lightning-template/datamodule_1.py", line 94, in setup
    full_dataset = BoundingBoxDataset(img_dir=os.path.join(self.data_root,self.train_str),
  File "/home/philipdb/dat2/datsyn_project/pytorch-lightning-template/datamodule_1.py", line 19, in __init__
    self.unique_images = self.annotations['img_number'].tolist()
  File "/home/philipdb/anaconda3/envs/tdt4265/lib/python3.10/site-packages/pandas/core/frame.py", line 4090, in __getitem__
    indexer = self.columns.get_loc(key)
  File "/home/philipdb/anaconda3/envs/tdt4265/lib/python3.10/site-packages/pandas/core/indexes/base.py", line 3812, in get_loc
    raise KeyError(key) from err
KeyError: 'img_number'