Using bfloat16 Automatic Mixed Precision (AMP)
GPU available: True (cuda), used: True
TPU available: False, using: 0 TPU cores
IPU available: False, using: 0 IPUs
HPU available: False, using: 0 HPUs
LOCAL_RANK: 0 - CUDA_VISIBLE_DEVICES: [0]
  | Name       | Type               | Params
--------------------------------------------------
0 | model      | ResNet             | 23.5 M
1 | bbox_head  | Linear             | 213 K
2 | bbox_class | Linear             | 106 K
3 | acc_fn     | MulticlassAccuracy | 0
--------------------------------------------------
23.8 M    Trainable params
0         Non-trainable params
23.8 M    Total params
95.311    Total estimated model params size (MB)
Traceback (most recent call last):
  File "/home/philipdb/dat2/datsyn_project/pytorch-lightning-template/trainer.py", line 103, in <module>
    trainer.fit(model, datamodule=dm)
  File "/home/philipdb/anaconda3/envs/tdt4265/lib/python3.10/site-packages/lightning/pytorch/trainer/trainer.py", line 532, in fit
    call._call_and_handle_interrupt(
  File "/home/philipdb/anaconda3/envs/tdt4265/lib/python3.10/site-packages/lightning/pytorch/trainer/call.py", line 43, in _call_and_handle_interrupt
    return trainer_fn(*args, **kwargs)
  File "/home/philipdb/anaconda3/envs/tdt4265/lib/python3.10/site-packages/lightning/pytorch/trainer/trainer.py", line 571, in _fit_impl
    self._run(model, ckpt_path=ckpt_path)
  File "/home/philipdb/anaconda3/envs/tdt4265/lib/python3.10/site-packages/lightning/pytorch/trainer/trainer.py", line 980, in _run
    results = self._run_stage()
  File "/home/philipdb/anaconda3/envs/tdt4265/lib/python3.10/site-packages/lightning/pytorch/trainer/trainer.py", line 1021, in _run_stage
    self._run_sanity_check()
  File "/home/philipdb/anaconda3/envs/tdt4265/lib/python3.10/site-packages/lightning/pytorch/trainer/trainer.py", line 1050, in _run_sanity_check
    val_loop.run()
  File "/home/philipdb/anaconda3/envs/tdt4265/lib/python3.10/site-packages/lightning/pytorch/loops/utilities.py", line 181, in _decorator
    return loop_run(self, *args, **kwargs)
  File "/home/philipdb/anaconda3/envs/tdt4265/lib/python3.10/site-packages/lightning/pytorch/loops/evaluation_loop.py", line 108, in run
    batch, batch_idx, dataloader_idx = next(data_fetcher)
  File "/home/philipdb/anaconda3/envs/tdt4265/lib/python3.10/site-packages/lightning/pytorch/loops/fetchers.py", line 126, in __next__
    batch = super().__next__()
  File "/home/philipdb/anaconda3/envs/tdt4265/lib/python3.10/site-packages/lightning/pytorch/loops/fetchers.py", line 58, in __next__
    batch = next(self.iterator)
  File "/home/philipdb/anaconda3/envs/tdt4265/lib/python3.10/site-packages/lightning/pytorch/utilities/combined_loader.py", line 285, in __next__
    out = next(self._iterator)
  File "/home/philipdb/anaconda3/envs/tdt4265/lib/python3.10/site-packages/lightning/pytorch/utilities/combined_loader.py", line 123, in __next__
    out = next(self.iterators[0])
  File "/home/philipdb/anaconda3/envs/tdt4265/lib/python3.10/site-packages/torch/utils/data/dataloader.py", line 631, in __next__
    data = self._next_data()
  File "/home/philipdb/anaconda3/envs/tdt4265/lib/python3.10/site-packages/torch/utils/data/dataloader.py", line 1346, in _next_data
    return self._process_data(data)
  File "/home/philipdb/anaconda3/envs/tdt4265/lib/python3.10/site-packages/torch/utils/data/dataloader.py", line 1372, in _process_data
    data.reraise()
  File "/home/philipdb/anaconda3/envs/tdt4265/lib/python3.10/site-packages/torch/_utils.py", line 722, in reraise
    raise exception
AttributeError: Caught AttributeError in DataLoader worker process 0.
Original Traceback (most recent call last):
  File "/home/philipdb/anaconda3/envs/tdt4265/lib/python3.10/site-packages/torch/utils/data/_utils/worker.py", line 308, in _worker_loop
    data = fetcher.fetch(index)
  File "/home/philipdb/anaconda3/envs/tdt4265/lib/python3.10/site-packages/torch/utils/data/_utils/fetch.py", line 49, in fetch
    data = self.dataset.__getitems__(possibly_batched_index)
  File "/home/philipdb/anaconda3/envs/tdt4265/lib/python3.10/site-packages/torch/utils/data/dataset.py", line 399, in __getitems__
    return [self.dataset[self.indices[idx]] for idx in indices]
  File "/home/philipdb/anaconda3/envs/tdt4265/lib/python3.10/site-packages/torch/utils/data/dataset.py", line 399, in <listcomp>
    return [self.dataset[self.indices[idx]] for idx in indices]
  File "/home/philipdb/dat2/datsyn_project/pytorch-lightning-template/datamodule_1.py", line 44, in __getitem__
    image = io.load_image(img_path)
AttributeError: module 'torchvision.io' has no attribute 'load_image'. Did you mean: 'read_image'?
Traceback (most recent call last):
  File "/home/philipdb/dat2/datsyn_project/pytorch-lightning-template/trainer.py", line 103, in <module>
    trainer.fit(model, datamodule=dm)
  File "/home/philipdb/anaconda3/envs/tdt4265/lib/python3.10/site-packages/lightning/pytorch/trainer/trainer.py", line 532, in fit
    call._call_and_handle_interrupt(
  File "/home/philipdb/anaconda3/envs/tdt4265/lib/python3.10/site-packages/lightning/pytorch/trainer/call.py", line 43, in _call_and_handle_interrupt
    return trainer_fn(*args, **kwargs)
  File "/home/philipdb/anaconda3/envs/tdt4265/lib/python3.10/site-packages/lightning/pytorch/trainer/trainer.py", line 571, in _fit_impl
    self._run(model, ckpt_path=ckpt_path)
  File "/home/philipdb/anaconda3/envs/tdt4265/lib/python3.10/site-packages/lightning/pytorch/trainer/trainer.py", line 980, in _run
    results = self._run_stage()
  File "/home/philipdb/anaconda3/envs/tdt4265/lib/python3.10/site-packages/lightning/pytorch/trainer/trainer.py", line 1021, in _run_stage
    self._run_sanity_check()
  File "/home/philipdb/anaconda3/envs/tdt4265/lib/python3.10/site-packages/lightning/pytorch/trainer/trainer.py", line 1050, in _run_sanity_check
    val_loop.run()
  File "/home/philipdb/anaconda3/envs/tdt4265/lib/python3.10/site-packages/lightning/pytorch/loops/utilities.py", line 181, in _decorator
    return loop_run(self, *args, **kwargs)
  File "/home/philipdb/anaconda3/envs/tdt4265/lib/python3.10/site-packages/lightning/pytorch/loops/evaluation_loop.py", line 108, in run
    batch, batch_idx, dataloader_idx = next(data_fetcher)
  File "/home/philipdb/anaconda3/envs/tdt4265/lib/python3.10/site-packages/lightning/pytorch/loops/fetchers.py", line 126, in __next__
    batch = super().__next__()
  File "/home/philipdb/anaconda3/envs/tdt4265/lib/python3.10/site-packages/lightning/pytorch/loops/fetchers.py", line 58, in __next__
    batch = next(self.iterator)
  File "/home/philipdb/anaconda3/envs/tdt4265/lib/python3.10/site-packages/lightning/pytorch/utilities/combined_loader.py", line 285, in __next__
    out = next(self._iterator)
  File "/home/philipdb/anaconda3/envs/tdt4265/lib/python3.10/site-packages/lightning/pytorch/utilities/combined_loader.py", line 123, in __next__
    out = next(self.iterators[0])
  File "/home/philipdb/anaconda3/envs/tdt4265/lib/python3.10/site-packages/torch/utils/data/dataloader.py", line 631, in __next__
    data = self._next_data()
  File "/home/philipdb/anaconda3/envs/tdt4265/lib/python3.10/site-packages/torch/utils/data/dataloader.py", line 1346, in _next_data
    return self._process_data(data)
  File "/home/philipdb/anaconda3/envs/tdt4265/lib/python3.10/site-packages/torch/utils/data/dataloader.py", line 1372, in _process_data
    data.reraise()
  File "/home/philipdb/anaconda3/envs/tdt4265/lib/python3.10/site-packages/torch/_utils.py", line 722, in reraise
    raise exception
AttributeError: Caught AttributeError in DataLoader worker process 0.
Original Traceback (most recent call last):
  File "/home/philipdb/anaconda3/envs/tdt4265/lib/python3.10/site-packages/torch/utils/data/_utils/worker.py", line 308, in _worker_loop
    data = fetcher.fetch(index)
  File "/home/philipdb/anaconda3/envs/tdt4265/lib/python3.10/site-packages/torch/utils/data/_utils/fetch.py", line 49, in fetch
    data = self.dataset.__getitems__(possibly_batched_index)
  File "/home/philipdb/anaconda3/envs/tdt4265/lib/python3.10/site-packages/torch/utils/data/dataset.py", line 399, in __getitems__
    return [self.dataset[self.indices[idx]] for idx in indices]
  File "/home/philipdb/anaconda3/envs/tdt4265/lib/python3.10/site-packages/torch/utils/data/dataset.py", line 399, in <listcomp>
    return [self.dataset[self.indices[idx]] for idx in indices]
  File "/home/philipdb/dat2/datsyn_project/pytorch-lightning-template/datamodule_1.py", line 44, in __getitem__
    image = io.load_image(img_path)
AttributeError: module 'torchvision.io' has no attribute 'load_image'. Did you mean: 'read_image'?